<?xml version="1.0" ?>
<robot name = "little_car">
	<link name = "base_link">
		<visual>
			<origin xyz="0 0 0.05" rpy="0 0 0" /> 
			<geometry>
				<box size="0.2 0.3 0.1" />
		</geometry>
		<material name="blue">
				<color rgba="0 .5 .8 1"/>
		</material>
		</visual>
		<collision>
			<geometry>
				<box size="0.21 0.31 0.11"/>
			</geometry>
		</collision>
				<mass value="10"/>
	</link>

	<!-- front wheel -->
	<link name="wheel_1" > 
		<visual>
		<geometry>
			<cylinder length="0.05" radius="0.05" />
		</geometry>
		</visual>
		<collision>
			<geometry>
				<cylinder length="0.05" radius="0.05" />
			</geometry>
		</collision>
			<mass value="10"/>
	</link>

	<link name="wheel_2" >
		<visual>
		<geometry>
			<cylinder length="0.05" radius="0.05" />
		</geometry>
		</visual>
		<collision>
			<geometry>
				<cylinder length="0.05" radius="0.05" />
			</geometry>
		</collision>
			<mass value="10"/>
	</link>


	<link name="wheel_3" >
		<visual>
		<geometry>
			<cylinder length="0.05" radius="0.05" />
		</geometry>
		</visual>
		<collision>
			<geometry>
				<cylinder length="0.05" radius="0.05" />
			</geometry>
		</collision>
			<mass value="10"/>
	</link>


	<link name="wheel_4" >
		<visual>
		<geometry>
			<cylinder length="0.05" radius="0.05" />
		</geometry>
		</visual>
		<collision>
			<geometry>
				<cylinder length="0.05" radius="0.05" />
			</geometry>
	</collision>
			<mass value="10"/>
	</link>

	<joint name="base_to_wheel_1" type="continuous">
		<parent link="base_link"/>
		<child link="wheel_1" />
		<axis xyz=" 0 0 1" />
		<origin xyz="0.1 0.1 0" rpy="0 1.570795 0" />
		<joint_properties damping="20.0" friction="20.0"/>
	</joint>

	<joint name="base_to_wheel_2" type="continuous">
		<parent link="base_link"/>
		<child link="wheel_2" />
		<axis xyz="0 0 1" />
		<origin xyz="-0.1 0.1 0" rpy="0 1.570795 0" />
		<joint_properties damping="20.0" friction="20.0"/>
	</joint>


	<joint name="base_to_wheel_3" type="continuous">
		<parent link="base_link"/>
		<child link="wheel_3" />
		<origin xyz="0.1 -0.1 0" rpy="0 1.570795 0" />
		<axis xyz="0 0 1" />
		<joint_properties damping="20.0" friction="20.0"/>
	</joint>


	<joint name="base_to_wheel_4" type="continuous">
		<parent link="base_link"/>
		<child link="wheel_4" />
		<origin xyz="-0.1 -0.1 0" rpy="0 1.570795 0" />
		<axis xyz="0 0 1" />
		<joint_properties damping="20.0" friction="20.0"/>
	</joint>
</robot>
